<?xml version="1.0" ?>
<robot name="simple_box" xmlns:xacro="http://www.ros.org/wiki/xacro">

   
  <gazebo >
<plugin name="gimbal_controller" filename="libgazebo_poltergeist_gimbal_plugin.so"/>
  </gazebo>
 
    <link name='g_base_link'>
      <origin xyz="0 0 0"/>
      <inertial>
        <mass value="1000.0" />
      <inertia  ixx="100.0" ixy="0.0"  ixz="0.0"  iyy="100.0"  iyz="0.0"  izz="100.0" />
        <origin xyz="0 0 0" />
      </inertial>
      <self_collide>0</self_collide>
      <kinematic>0</kinematic>
      <visual >
        <origin xyz="0 0 0"/>
        <geometry>
        <box size="4 4 0.05" />
       </geometry>
      </visual>
      <collision >
        <origin xyz="0 0 0"/>
        <geometry>
        <box size="4 4 0.05" />
       </geometry>
      </collision>
    </link>

   <joint name="g_base_link__up_stick_link" type="fixed">
    <parent link="g_base_link"/>
    <child link="up_stick_link"/>
    <axis xyz="1 0 0"/>
    <dynamics damping="0"/>
    <dynamics friction="0"/>
    <limit velocity="1e+16" effort="1e+16" />
    <origin xyz="0 0 0" rpy="0 0 0"/>
  </joint>

    <link name='up_stick_link'>
      <origin xyz="0 0 0"/>
      <inertial>
        <mass value="0.001" />
      <inertia  ixx="1.0" ixy="0.0"  ixz="0.0"  iyy="1.0"  iyz="0.0"  izz="1.0" />
        <origin xyz="0 0 0" />
      </inertial>
      <self_collide>0</self_collide>
      <kinematic>0</kinematic>
      <visual >
        <origin xyz="0 0 0.5"/>
        <geometry>
        <box size="0.05 0.05 1" />
       </geometry>
      </visual>
      <visual >
        <origin xyz="0.25 0 1"/>
        <geometry>
        <box size="0.5 0.05 0.05" />
       </geometry>
      </visual>
      <visual >
        <origin xyz="0.5 0 0.9"/>
        <geometry>
        <box size="0.05 0.05 0.2" />
       </geometry>
      </visual>
    </link>

<link name='camera_mount_link'>
<visual >
        <origin xyz="0 0.05 0"/>
        <geometry>
        <box size="0.05 0.1 0.05" />
       </geometry>
      </visual>
<inertial>
        <mass value="0.001" />
      <inertia  ixx="1.0" ixy="0.0"  ixz="0.0"  iyy="1.0"  iyz="0.0"  izz="1.0" />
        <origin xyz="0 0 0" />
      </inertial>
</link>


  <joint name="my_joint" type="continuous">
    <parent link="up_stick_link"/>
    <child link="camera_mount_link"/>
    <axis xyz="1 0 0"/>
    <dynamics damping="0"/>
    <dynamics friction="0"/>
    <limit velocity="1e+16" effort="1e+16" />
    <origin xyz="0.5 0 0.8" rpy="0 0 0"/>
  </joint>

   
</robot>
